{'2020-06-25 01:36:05.869860': 'Traceback (most recent call last):\n  File "C:\\Users\\domin\\PycharmProjects\\td-backend\\flask_apis\\User.py", line 39, in registration\n    db_access.create_document(password, birthday)\n  File "C:\\Users\\domin\\PycharmProjects\\td-backend\\database_access\\DbAccess.py", line 49, in create_document\n    file = open(r"D:\\Users\\Dominic\\training-diary-app\\database_access\\initial_data", "rb")\nFileNotFoundError: [Errno 2] No such file or directory: \'D:\\\\Users\\\\Dominic\\\\training-diary-app\\\\database_access\\\\initial_data\'\n'}
{'2020-06-25 01:36:19.843346': 'Traceback (most recent call last):\n  File "C:\\Users\\domin\\PycharmProjects\\td-backend\\flask_apis\\User.py", line 39, in registration\n    db_access.create_document(password, birthday)\n  File "C:\\Users\\domin\\PycharmProjects\\td-backend\\database_access\\DbAccess.py", line 49, in create_document\n    file = open(r"D:\\Users\\Dominic\\training-diary-app\\database_access\\initial_data", "rb")\nFileNotFoundError: [Errno 2] No such file or directory: \'D:\\\\Users\\\\Dominic\\\\training-diary-app\\\\database_access\\\\initial_data\'\n'}
{'2020-06-28 01:43:16.004568': 'Traceback (most recent call last):\n  File "C:\\Users\\domin\\PycharmProjects\\td-backend\\flask_apis\\User.py", line 66, in get_all_data\n    return self.__generate_success_response(self.__auth.get_db_access().get_all_data())\n  File "C:\\Users\\domin\\PycharmProjects\\td-backend\\database_access\\DbAccess.py", line 28, in get_all_data\n    data = self.__document.copy()\nAttributeError: \'NoneType\' object has no attribute \'copy\'\n'}
{'2020-06-28 01:50:10.286034': 'Traceback (most recent call last):\n  File "C:\\Users\\domin\\PycharmProjects\\td-backend\\flask_apis\\User.py", line 66, in get_all_data\n    return self.__generate_success_response(self.__auth.get_db_access().get_all_data())\n  File "C:\\Users\\domin\\PycharmProjects\\td-backend\\database_access\\DbAccess.py", line 28, in get_all_data\n    data = self.__document.copy()\nAttributeError: \'NoneType\' object has no attribute \'copy\'\n'}
{'2020-06-28 01:52:46.305049': 'Traceback (most recent call last):\n  File "C:\\Users\\domin\\PycharmProjects\\td-backend\\flask_apis\\User.py", line 66, in get_all_data\n    return self.__generate_success_response(self.__auth.get_db_access().get_all_data())\n  File "C:\\Users\\domin\\PycharmProjects\\td-backend\\database_access\\DbAccess.py", line 28, in get_all_data\n    data = self.__document.copy()\nAttributeError: \'NoneType\' object has no attribute \'copy\'\n'}
{'2020-06-28 01:56:58.385687': 'Traceback (most recent call last):\n  File "C:\\Users\\domin\\PycharmProjects\\td-backend\\flask_apis\\User.py", line 66, in get_all_data\n    return self.__generate_success_response(self.__auth.get_db_access().get_all_data())\n  File "C:\\Users\\domin\\PycharmProjects\\td-backend\\database_access\\DbAccess.py", line 28, in get_all_data\n    data = self.__document.copy()\nAttributeError: \'NoneType\' object has no attribute \'copy\'\n'}
{'2020-06-28 02:00:01.889090': 'Traceback (most recent call last):\n  File "C:\\Users\\domin\\PycharmProjects\\td-backend\\flask_apis\\User.py", line 66, in get_all_data\n    return self.__generate_success_response(self.__auth.get_db_access().get_all_data())\n  File "C:\\Users\\domin\\PycharmProjects\\td-backend\\database_access\\DbAccess.py", line 28, in get_all_data\n    data = self.__document.copy()\nAttributeError: \'NoneType\' object has no attribute \'copy\'\n'}
{'2020-06-28 02:30:53.554848': 'Traceback (most recent call last):\n  File "C:\\Users\\domin\\PycharmProjects\\td-backend\\flask_apis\\User.py", line 66, in get_all_data\n    return self.__generate_success_response(self.__auth.get_db_access().get_all_data())\n  File "C:\\Users\\domin\\PycharmProjects\\td-backend\\database_access\\DbAccess.py", line 28, in get_all_data\n    data = self.__document.copy()\nAttributeError: \'NoneType\' object has no attribute \'copy\'\n'}
{'2020-06-28 02:34:32.610089': 'Traceback (most recent call last):\n  File "C:\\Users\\domin\\PycharmProjects\\td-backend\\flask_apis\\User.py", line 66, in get_all_data\n    return self.__generate_success_response(self.__auth.get_db_access().get_all_data())\n  File "C:\\Users\\domin\\PycharmProjects\\td-backend\\database_access\\DbAccess.py", line 28, in get_all_data\n    data = self.__document.copy()\nAttributeError: \'NoneType\' object has no attribute \'copy\'\n'}
{'2020-07-11 01:19:18.059120': 'Traceback (most recent call last):\n  File "D:\\Users\\Dominic\\training-diary-app\\flask_apis\\User.py", line 39, in registration\n    db_access.create_document(password, birthday)\n  File "D:\\Users\\Dominic\\training-diary-app\\database_access\\DbAccess.py", line 49, in create_document\n    file = open(r"C:\\Users\\domin\\PycharmProjects\\td-backend\\database_access\\initial_data", "rb")\nFileNotFoundError: [Errno 2] No such file or directory: \'C:\\\\Users\\\\domin\\\\PycharmProjects\\\\td-backend\\\\database_access\\\\initial_data\'\n'}
{'2020-07-11 01:19:25.780236': 'Traceback (most recent call last):\n  File "D:\\Users\\Dominic\\training-diary-app\\flask_apis\\User.py", line 39, in registration\n    db_access.create_document(password, birthday)\n  File "D:\\Users\\Dominic\\training-diary-app\\database_access\\DbAccess.py", line 49, in create_document\n    file = open(r"C:\\Users\\domin\\PycharmProjects\\td-backend\\database_access\\initial_data", "rb")\nFileNotFoundError: [Errno 2] No such file or directory: \'C:\\\\Users\\\\domin\\\\PycharmProjects\\\\td-backend\\\\database_access\\\\initial_data\'\n'}
{'2020-07-11 01:19:41.958369': 'Traceback (most recent call last):\n  File "D:\\Users\\Dominic\\training-diary-app\\flask_apis\\User.py", line 39, in registration\n    db_access.create_document(password, birthday)\n  File "D:\\Users\\Dominic\\training-diary-app\\database_access\\DbAccess.py", line 49, in create_document\n    file = open(r"C:\\Users\\domin\\PycharmProjects\\td-backend\\database_access\\initial_data", "rb")\nFileNotFoundError: [Errno 2] No such file or directory: \'C:\\\\Users\\\\domin\\\\PycharmProjects\\\\td-backend\\\\database_access\\\\initial_data\'\n'}
{'2020-07-11 01:23:49.691731': 'Traceback (most recent call last):\n  File "D:\\Users\\Dominic\\training-diary-app\\flask_apis\\User.py", line 66, in get_all_data\n    return self.__generate_success_response(self.__auth.get_db_access().get_all_data())\n  File "D:\\Users\\Dominic\\training-diary-app\\database_access\\DbAccess.py", line 28, in get_all_data\n    data = self.__document.copy()\nAttributeError: \'NoneType\' object has no attribute \'copy\'\n'}
{'2020-07-11 18:04:58.528736': 'Traceback (most recent call last):\n  File "D:\\Users\\Dominic\\training-diary-app\\flask_apis\\User.py", line 66, in get_all_data\n    return self.__generate_success_response(self.__auth.get_db_access().get_all_data())\n  File "D:\\Users\\Dominic\\training-diary-app\\database_access\\DbAccess.py", line 28, in get_all_data\n    data = self.__document.copy()\nAttributeError: \'NoneType\' object has no attribute \'copy\'\n'}
{'2020-07-11 18:21:30.164193': 'Traceback (most recent call last):\n  File "D:\\Users\\Dominic\\training-diary-app\\flask_apis\\User.py", line 66, in get_all_data\n    return self.__generate_success_response(self.__auth.get_db_access().get_all_data())\n  File "D:\\Users\\Dominic\\training-diary-app\\database_access\\DbAccess.py", line 28, in get_all_data\n    data = self.__document.copy()\nAttributeError: \'NoneType\' object has no attribute \'copy\'\n'}
{'2020-07-11 18:35:15.757503': 'Traceback (most recent call last):\n  File "D:\\Users\\Dominic\\training-diary-app\\flask_apis\\User.py", line 66, in get_all_data\n    return self.__generate_success_response(self.__auth.get_db_access().get_all_data())\n  File "D:\\Users\\Dominic\\training-diary-app\\database_access\\DbAccess.py", line 28, in get_all_data\n    data = self.__document.copy()\nAttributeError: \'NoneType\' object has no attribute \'copy\'\n'}
{'2020-07-11 18:42:26.840138': 'Traceback (most recent call last):\n  File "D:\\Users\\Dominic\\training-diary-app\\flask_apis\\User.py", line 66, in get_all_data\n    return self.__generate_success_response(self.__auth.get_db_access().get_all_data())\n  File "D:\\Users\\Dominic\\training-diary-app\\database_access\\DbAccess.py", line 28, in get_all_data\n    data = self.__document.copy()\nAttributeError: \'NoneType\' object has no attribute \'copy\'\n'}
{'2020-07-12 03:36:56.130417': 'Traceback (most recent call last):\n  File "D:\\Users\\Dominic\\training-diary-app\\flask_apis\\User.py", line 66, in get_all_data\n    return self.__generate_success_response(self.__auth.get_db_access().get_all_data())\n  File "D:\\Users\\Dominic\\training-diary-app\\database_access\\DbAccess.py", line 28, in get_all_data\n    data = self.__document.copy()\nAttributeError: \'NoneType\' object has no attribute \'copy\'\n'}
{'2020-07-13 02:07:03.144032': 'Traceback (most recent call last):\n  File "D:\\Users\\Dominic\\training-diary-app\\flask_apis\\User.py", line 66, in get_all_data\n    return self.__generate_success_response(self.__auth.get_db_access().get_all_data())\n  File "D:\\Users\\Dominic\\training-diary-app\\database_access\\DbAccess.py", line 28, in get_all_data\n    data = self.__document.copy()\nAttributeError: \'NoneType\' object has no attribute \'copy\'\n'}
{'2020-07-13 02:09:19.801965': 'Traceback (most recent call last):\n  File "D:\\Users\\Dominic\\training-diary-app\\flask_apis\\User.py", line 66, in get_all_data\n    return self.__generate_success_response(self.__auth.get_db_access().get_all_data())\n  File "D:\\Users\\Dominic\\training-diary-app\\database_access\\DbAccess.py", line 28, in get_all_data\n    data = self.__document.copy()\nAttributeError: \'NoneType\' object has no attribute \'copy\'\n'}
{'2020-07-23 21:21:39.249573': 'Traceback (most recent call last):\n  File "D:\\Users\\Dominic\\training-diary-app\\flask_apis\\User.py", line 66, in get_all_data\n    return self.__generate_success_response(self.__auth.get_db_access().get_all_data())\n  File "D:\\Users\\Dominic\\training-diary-app\\database_access\\DbAccess.py", line 28, in get_all_data\n    data = self.__document.copy()\nAttributeError: \'NoneType\' object has no attribute \'copy\'\n'}
{'2020-07-23 21:31:01.386306': 'Traceback (most recent call last):\n  File "D:\\Users\\Dominic\\training-diary-app\\flask_apis\\User.py", line 66, in get_all_data\n    return self.__generate_success_response(self.__auth.get_db_access().get_all_data())\n  File "D:\\Users\\Dominic\\training-diary-app\\database_access\\DbAccess.py", line 28, in get_all_data\n    data = self.__document.copy()\nAttributeError: \'NoneType\' object has no attribute \'copy\'\n'}
{'2020-07-24 12:29:37.296828': 'Traceback (most recent call last):\n  File "D:\\Users\\Dominic\\training-diary-app\\flask_apis\\User.py", line 66, in get_all_data\n    return self.__generate_success_response(self.__auth.get_db_access().get_all_data())\n  File "D:\\Users\\Dominic\\training-diary-app\\database_access\\DbAccess.py", line 28, in get_all_data\n    data = self.__document.copy()\nAttributeError: \'NoneType\' object has no attribute \'copy\'\n'}
{'2020-07-24 15:55:07.647301': 'Traceback (most recent call last):\n  File "D:\\Users\\Dominic\\training-diary-app\\flask_apis\\User.py", line 66, in get_all_data\n    return self.__generate_success_response(self.__auth.get_db_access().get_all_data())\n  File "D:\\Users\\Dominic\\training-diary-app\\database_access\\DbAccess.py", line 28, in get_all_data\n    data = self.__document.copy()\nAttributeError: \'NoneType\' object has no attribute \'copy\'\n'}
{'2020-07-27 16:54:27.358656': 'Traceback (most recent call last):\n  File "D:\\Users\\Dominic\\training-diary-app\\flask_apis\\User.py", line 66, in get_all_data\n    return self.__generate_success_response(self.__auth.get_db_access().get_all_data())\n  File "D:\\Users\\Dominic\\training-diary-app\\database_access\\DbAccess.py", line 28, in get_all_data\n    data = self.__document.copy()\nAttributeError: \'NoneType\' object has no attribute \'copy\'\n'}
{'2020-07-27 17:04:24.599303': 'Traceback (most recent call last):\n  File "D:\\Users\\Dominic\\training-diary-app\\flask_apis\\User.py", line 66, in get_all_data\n    return self.__generate_success_response(self.__auth.get_db_access().get_all_data())\n  File "D:\\Users\\Dominic\\training-diary-app\\database_access\\DbAccess.py", line 28, in get_all_data\n    data = self.__document.copy()\nAttributeError: \'NoneType\' object has no attribute \'copy\'\n'}
{'2020-07-27 17:14:54.131028': 'Traceback (most recent call last):\n  File "D:\\Users\\Dominic\\training-diary-app\\flask_apis\\User.py", line 66, in get_all_data\n    return self.__generate_success_response(self.__auth.get_db_access().get_all_data())\n  File "D:\\Users\\Dominic\\training-diary-app\\database_access\\DbAccess.py", line 28, in get_all_data\n    data = self.__document.copy()\nAttributeError: \'NoneType\' object has no attribute \'copy\'\n'}
{'2020-07-27 17:19:01.732412': 'Traceback (most recent call last):\n  File "D:\\Users\\Dominic\\training-diary-app\\flask_apis\\User.py", line 66, in get_all_data\n    return self.__generate_success_response(self.__auth.get_db_access().get_all_data())\n  File "D:\\Users\\Dominic\\training-diary-app\\database_access\\DbAccess.py", line 28, in get_all_data\n    data = self.__document.copy()\nAttributeError: \'NoneType\' object has no attribute \'copy\'\n'}
{'2020-07-27 17:45:08.787309': 'Traceback (most recent call last):\n  File "D:\\Users\\Dominic\\training-diary-app\\flask_apis\\User.py", line 66, in get_all_data\n    return self.__generate_success_response(self.__auth.get_db_access().get_all_data())\n  File "D:\\Users\\Dominic\\training-diary-app\\database_access\\DbAccess.py", line 28, in get_all_data\n    data = self.__document.copy()\nAttributeError: \'NoneType\' object has no attribute \'copy\'\n'}
{'2020-07-27 17:47:52.507741': 'Traceback (most recent call last):\n  File "D:\\Users\\Dominic\\training-diary-app\\flask_apis\\User.py", line 66, in get_all_data\n    return self.__generate_success_response(self.__auth.get_db_access().get_all_data())\n  File "D:\\Users\\Dominic\\training-diary-app\\database_access\\DbAccess.py", line 28, in get_all_data\n    data = self.__document.copy()\nAttributeError: \'NoneType\' object has no attribute \'copy\'\n'}
{'2020-07-27 17:57:57.944087': 'Traceback (most recent call last):\n  File "D:\\Users\\Dominic\\training-diary-app\\flask_apis\\User.py", line 66, in get_all_data\n    return self.__generate_success_response(self.__auth.get_db_access().get_all_data())\n  File "D:\\Users\\Dominic\\training-diary-app\\database_access\\DbAccess.py", line 28, in get_all_data\n    data = self.__document.copy()\nAttributeError: \'NoneType\' object has no attribute \'copy\'\n'}
{'2020-07-28 16:30:11.846152': 'Traceback (most recent call last):\n  File "D:\\Users\\Dominic\\training-diary-app\\flask_apis\\User.py", line 66, in get_all_data\n    return self.__generate_success_response(self.__auth.get_db_access().get_all_data())\n  File "D:\\Users\\Dominic\\training-diary-app\\database_access\\DbAccess.py", line 28, in get_all_data\n    data = self.__document.copy()\nAttributeError: \'NoneType\' object has no attribute \'copy\'\n'}
{'2020-07-28 16:32:55.135233': 'Traceback (most recent call last):\n  File "D:\\Users\\Dominic\\training-diary-app\\flask_apis\\User.py", line 66, in get_all_data\n    return self.__generate_success_response(self.__auth.get_db_access().get_all_data())\n  File "D:\\Users\\Dominic\\training-diary-app\\database_access\\DbAccess.py", line 28, in get_all_data\n    data = self.__document.copy()\nAttributeError: \'NoneType\' object has no attribute \'copy\'\n'}
{'2020-07-28 17:50:45.528006': 'Traceback (most recent call last):\n  File "D:\\Users\\Dominic\\training-diary-app\\flask_apis\\User.py", line 66, in get_all_data\n    return self.__generate_success_response(self.__auth.get_db_access().get_all_data())\n  File "D:\\Users\\Dominic\\training-diary-app\\database_access\\DbAccess.py", line 28, in get_all_data\n    data = self.__document.copy()\nAttributeError: \'NoneType\' object has no attribute \'copy\'\n'}
{'2020-07-31 18:21:04.551225': 'Traceback (most recent call last):\n  File "D:\\Users\\Dominic\\training-diary-app\\flask_apis\\User.py", line 66, in get_all_data\n    return self.__generate_success_response(self.__auth.get_db_access().get_all_data())\n  File "D:\\Users\\Dominic\\training-diary-app\\database_access\\DbAccess.py", line 28, in get_all_data\n    data = self.__document.copy()\nAttributeError: \'NoneType\' object has no attribute \'copy\'\n'}
{'2020-07-31 18:25:07.870551': 'Traceback (most recent call last):\n  File "D:\\Users\\Dominic\\training-diary-app\\flask_apis\\User.py", line 66, in get_all_data\n    return self.__generate_success_response(self.__auth.get_db_access().get_all_data())\n  File "D:\\Users\\Dominic\\training-diary-app\\database_access\\DbAccess.py", line 28, in get_all_data\n    data = self.__document.copy()\nAttributeError: \'NoneType\' object has no attribute \'copy\'\n'}
{'2020-08-02 14:47:36.766561': 'Traceback (most recent call last):\n  File "C:\\Users\\Dominic\\AppData\\Roaming\\Python\\Python37\\site-packages\\werkzeug\\wrappers\\base_response.py", line 298, in status_code\n    self._status = "%d %s" % (code, HTTP_STATUS_CODES[code].upper())\nKeyError: <Response 0 bytes [401 UNAUTHORIZED]>\n\nDuring handling of the above exception, another exception occurred:\n\nTraceback (most recent call last):\n  File "D:\\Users\\Dominic\\training-diary-app\\flask_apis\\User.py", line 67, in get_all_data\n    print(make_response({}, flask.Response(status=401)))\n  File "C:\\Users\\Dominic\\AppData\\Roaming\\Python\\Python37\\site-packages\\flask\\helpers.py", line 223, in make_response\n    return current_app.make_response(args)\n  File "C:\\Users\\Dominic\\AppData\\Roaming\\Python\\Python37\\site-packages\\flask\\app.py", line 2139, in make_response\n    rv.status_code = status\n  File "C:\\Users\\Dominic\\AppData\\Roaming\\Python\\Python37\\site-packages\\werkzeug\\wrappers\\base_response.py", line 300, in status_code\n    self._status = "%d UNKNOWN" % code\nTypeError: %d format: a number is required, not Response\n'}
{'2020-08-02 14:47:45.343605': 'Traceback (most recent call last):\n  File "C:\\Users\\Dominic\\AppData\\Roaming\\Python\\Python37\\site-packages\\werkzeug\\wrappers\\base_response.py", line 298, in status_code\n    self._status = "%d %s" % (code, HTTP_STATUS_CODES[code].upper())\nKeyError: <Response 0 bytes [401 UNAUTHORIZED]>\n\nDuring handling of the above exception, another exception occurred:\n\nTraceback (most recent call last):\n  File "D:\\Users\\Dominic\\training-diary-app\\flask_apis\\User.py", line 67, in get_all_data\n    print(make_response({}, flask.Response(status=401)))\n  File "C:\\Users\\Dominic\\AppData\\Roaming\\Python\\Python37\\site-packages\\flask\\helpers.py", line 223, in make_response\n    return current_app.make_response(args)\n  File "C:\\Users\\Dominic\\AppData\\Roaming\\Python\\Python37\\site-packages\\flask\\app.py", line 2139, in make_response\n    rv.status_code = status\n  File "C:\\Users\\Dominic\\AppData\\Roaming\\Python\\Python37\\site-packages\\werkzeug\\wrappers\\base_response.py", line 300, in status_code\n    self._status = "%d UNKNOWN" % code\nTypeError: %d format: a number is required, not Response\n'}
{'2020-08-03 00:35:31.696386': 'Traceback (most recent call last):\n  File "D:\\Users\\Dominic\\training-diary-app\\flask_apis\\User.py", line 68, in get_all_data\n    return make_response(self.__auth.get_db_access().get_all_data(), 200, response_header)\n  File "D:\\Users\\Dominic\\training-diary-app\\database_access\\DbAccess.py", line 28, in get_all_data\n    data = self.__document.copy()\nAttributeError: \'NoneType\' object has no attribute \'copy\'\n'}
{'2020-08-03 23:43:06.278379': 'Traceback (most recent call last):\n  File "C:\\Users\\Dominic\\training-diary\\training-diary-backend\\flask_apis\\User.py", line 65, in update_username_and_email\n    db_access.update_username_and_email(new_username, new_email)\n  File "C:\\Users\\Dominic\\training-diary\\training-diary-backend\\database_access\\DbAccess.py", line 40, in update_username_and_email\n    data._id = new_username\nAttributeError: \'dict\' object has no attribute \'_id\'\n'}
{'2020-08-03 23:44:40.611733': 'Traceback (most recent call last):\n  File "C:\\Users\\Dominic\\training-diary\\training-diary-backend\\flask_apis\\User.py", line 65, in update_username_and_email\n    db_access.update_username_and_email(new_username, new_email)\n  File "C:\\Users\\Dominic\\training-diary\\training-diary-backend\\database_access\\DbAccess.py", line 41, in update_username_and_email\n    data._id = new_username\nAttributeError: \'dict\' object has no attribute \'_id\'\n'}
{'2020-08-04 00:31:49.751197': 'Traceback (most recent call last):\n  File "C:\\Users\\Dominic\\training-diary\\training-diary-backend\\flask_apis\\User.py", line 83, in get_all_data\n    return make_response(self.__auth.get_db_access().get_all_data(), 200, response_header)\n  File "C:\\Users\\Dominic\\training-diary\\training-diary-backend\\database_access\\DbAccess.py", line 32, in get_all_data\n    data = self.__document.copy()\nAttributeError: \'NoneType\' object has no attribute \'copy\'\n'}
{'2020-08-04 00:32:09.010793': 'Traceback (most recent call last):\n  File "C:\\Users\\Dominic\\training-diary\\training-diary-backend\\flask_apis\\User.py", line 68, in update_username_and_email\n    db_access.update_username_and_email(update_body)\n  File "C:\\Users\\Dominic\\training-diary\\training-diary-backend\\database_access\\DbAccess.py", line 46, in update_username_and_email\n    self.__db.find_one_and_replace({"_id": self.__username}, updated_document)\n  File "D:\\Program Files\\lib\\site-packages\\pymongo\\collection.py", line 3339, in __call__\n    self.__name)\nTypeError: \'Collection\' object is not callable. If you meant to call the \'find_one_and_replace\' method on a \'Database\' object it is failing because no such method exists.\n'}
{'2020-08-04 00:34:08.091626': 'Traceback (most recent call last):\n  File "C:\\Users\\Dominic\\training-diary\\training-diary-backend\\flask_apis\\User.py", line 68, in update_username_and_email\n    db_access.update_username_and_email(update_body)\n  File "C:\\Users\\Dominic\\training-diary\\training-diary-backend\\database_access\\DbAccess.py", line 46, in update_username_and_email\n    self.__db.get_collection("td").find_one_and_replace({"_id": self.__username}, updated_document)\n  File "D:\\Program Files\\lib\\site-packages\\pymongo\\collection.py", line 3018, in find_one_and_replace\n    common.validate_ok_for_replace(replacement)\n  File "D:\\Program Files\\lib\\site-packages\\pymongo\\common.py", line 517, in validate_ok_for_replace\n    validate_is_mapping("replacement", replacement)\n  File "D:\\Program Files\\lib\\site-packages\\pymongo\\common.py", line 474, in validate_is_mapping\n    "collections.Mapping" % (option,))\nTypeError: replacement must be an instance of dict, bson.son.SON, or any other type that inherits from collections.Mapping\n'}
{'2020-08-04 00:36:17.806480': 'Traceback (most recent call last):\n  File "C:\\Users\\Dominic\\training-diary\\training-diary-backend\\flask_apis\\User.py", line 68, in update_username_and_email\n    db_access.update_username_and_email(update_body)\n  File "C:\\Users\\Dominic\\training-diary\\training-diary-backend\\database_access\\DbAccess.py", line 45, in update_username_and_email\n    self.__db.get_collection("td").find_one_and_replace({"_id": self.__username}, self.__document.update(update_body))\n  File "D:\\Program Files\\lib\\site-packages\\pymongo\\collection.py", line 3018, in find_one_and_replace\n    common.validate_ok_for_replace(replacement)\n  File "D:\\Program Files\\lib\\site-packages\\pymongo\\common.py", line 517, in validate_ok_for_replace\n    validate_is_mapping("replacement", replacement)\n  File "D:\\Program Files\\lib\\site-packages\\pymongo\\common.py", line 474, in validate_is_mapping\n    "collections.Mapping" % (option,))\nTypeError: replacement must be an instance of dict, bson.son.SON, or any other type that inherits from collections.Mapping\n'}
{'2020-08-04 00:37:06.949496': 'Traceback (most recent call last):\n  File "C:\\Users\\Dominic\\training-diary\\training-diary-backend\\flask_apis\\User.py", line 68, in update_username_and_email\n    db_access.update_username_and_email(update_body)\n  File "C:\\Users\\Dominic\\training-diary\\training-diary-backend\\database_access\\DbAccess.py", line 46, in update_username_and_email\n    self.__db.get_collection("td").find_one_and_replace({"_id": self.__username}, self.__document.update(update_body))\n  File "D:\\Program Files\\lib\\site-packages\\pymongo\\collection.py", line 3018, in find_one_and_replace\n    common.validate_ok_for_replace(replacement)\n  File "D:\\Program Files\\lib\\site-packages\\pymongo\\common.py", line 517, in validate_ok_for_replace\n    validate_is_mapping("replacement", replacement)\n  File "D:\\Program Files\\lib\\site-packages\\pymongo\\common.py", line 474, in validate_is_mapping\n    "collections.Mapping" % (option,))\nTypeError: replacement must be an instance of dict, bson.son.SON, or any other type that inherits from collections.Mapping\n'}
{'2020-08-04 00:38:44.507852': 'Traceback (most recent call last):\n  File "C:\\Users\\Dominic\\training-diary\\training-diary-backend\\flask_apis\\User.py", line 68, in update_username_and_email\n    db_access.update_username_and_email(update_body)\n  File "C:\\Users\\Dominic\\training-diary\\training-diary-backend\\database_access\\DbAccess.py", line 47, in update_username_and_email\n    self.__db.get_collection("td").find_one_and_replace({"_id": self.__username}, self.__document.update(update_body))\n  File "D:\\Program Files\\lib\\site-packages\\pymongo\\collection.py", line 3018, in find_one_and_replace\n    common.validate_ok_for_replace(replacement)\n  File "D:\\Program Files\\lib\\site-packages\\pymongo\\common.py", line 517, in validate_ok_for_replace\n    validate_is_mapping("replacement", replacement)\n  File "D:\\Program Files\\lib\\site-packages\\pymongo\\common.py", line 474, in validate_is_mapping\n    "collections.Mapping" % (option,))\nTypeError: replacement must be an instance of dict, bson.son.SON, or any other type that inherits from collections.Mapping\n'}
{'2020-08-04 00:39:46.613843': 'Traceback (most recent call last):\n  File "C:\\Users\\Dominic\\training-diary\\training-diary-backend\\flask_apis\\User.py", line 68, in update_username_and_email\n    db_access.update_username_and_email(update_body)\n  File "C:\\Users\\Dominic\\training-diary\\training-diary-backend\\database_access\\DbAccess.py", line 48, in update_username_and_email\n    self.__db.get_collection("td").find_one_and_replace({"_id": self.__username}, self.__document.update(update_body))\n  File "D:\\Program Files\\lib\\site-packages\\pymongo\\collection.py", line 3018, in find_one_and_replace\n    common.validate_ok_for_replace(replacement)\n  File "D:\\Program Files\\lib\\site-packages\\pymongo\\common.py", line 517, in validate_ok_for_replace\n    validate_is_mapping("replacement", replacement)\n  File "D:\\Program Files\\lib\\site-packages\\pymongo\\common.py", line 474, in validate_is_mapping\n    "collections.Mapping" % (option,))\nTypeError: replacement must be an instance of dict, bson.son.SON, or any other type that inherits from collections.Mapping\n'}
{'2020-08-04 00:41:01.130331': 'Traceback (most recent call last):\n  File "C:\\Users\\Dominic\\training-diary\\training-diary-backend\\flask_apis\\User.py", line 68, in update_username_and_email\n    db_access.update_username_and_email(update_body)\n  File "C:\\Users\\Dominic\\training-diary\\training-diary-backend\\database_access\\DbAccess.py", line 46, in update_username_and_email\n    self.__db.get_collection("td").find_one_and_replace({"_id": self.__username}, self.__document)\n  File "D:\\Program Files\\lib\\site-packages\\pymongo\\collection.py", line 3022, in find_one_and_replace\n    session=session, **kwargs)\n  File "D:\\Program Files\\lib\\site-packages\\pymongo\\collection.py", line 2885, in __find_and_modify\n    write_concern.acknowledged, _find_and_modify, session)\n  File "D:\\Program Files\\lib\\site-packages\\pymongo\\mongo_client.py", line 1491, in _retryable_write\n    return self._retry_with_session(retryable, func, s, None)\n  File "D:\\Program Files\\lib\\site-packages\\pymongo\\mongo_client.py", line 1384, in _retry_with_session\n    return func(session, sock_info, retryable)\n  File "D:\\Program Files\\lib\\site-packages\\pymongo\\collection.py", line 2879, in _find_and_modify\n    user_fields=_FIND_AND_MODIFY_DOC_FIELDS)\n  File "D:\\Program Files\\lib\\site-packages\\pymongo\\collection.py", line 250, in _command\n    user_fields=user_fields)\n  File "D:\\Program Files\\lib\\site-packages\\pymongo\\pool.py", line 613, in command\n    user_fields=user_fields)\n  File "D:\\Program Files\\lib\\site-packages\\pymongo\\network.py", line 167, in command\n    parse_write_concern_error=parse_write_concern_error)\n  File "D:\\Program Files\\lib\\site-packages\\pymongo\\helpers.py", line 159, in _check_command_response\n    raise OperationFailure(msg % errmsg, code, response)\npymongo.errors.OperationFailure: After applying the update, the (immutable) field \'_id\' was found to have been altered to _id: "dominic"\n'}
{'2020-08-04 00:44:29.747950': 'Traceback (most recent call last):\n  File "C:\\Users\\Dominic\\training-diary\\training-diary-backend\\flask_apis\\User.py", line 83, in get_all_data\n    return make_response(self.__auth.get_db_access().get_all_data(), 200, response_header)\n  File "C:\\Users\\Dominic\\training-diary\\training-diary-backend\\database_access\\DbAccess.py", line 32, in get_all_data\n    data = self.__document.copy()\nAttributeError: \'NoneType\' object has no attribute \'copy\'\n'}
{'2020-08-04 00:47:52.733626': 'Traceback (most recent call last):\n  File "C:\\Users\\Dominic\\training-diary\\training-diary-backend\\flask_apis\\User.py", line 83, in get_all_data\n    return make_response(self.__auth.get_db_access().get_all_data(), 200, response_header)\n  File "C:\\Users\\Dominic\\training-diary\\training-diary-backend\\database_access\\DbAccess.py", line 32, in get_all_data\n    data = self.__document.copy()\nAttributeError: \'NoneType\' object has no attribute \'copy\'\n'}
{'2020-08-05 15:38:34.903245': 'Traceback (most recent call last):\n  File "C:\\Users\\Dominic\\training-diary\\training-diary-backend\\flask_apis\\User.py", line 104, in get_all_data\n    return make_response(self.__auth.get_db_access().get_all_data(), 200, response_header)\n  File "C:\\Users\\Dominic\\training-diary\\training-diary-backend\\database_access\\DbAccess.py", line 36, in get_all_data\n    data = self.__document.copy()\nAttributeError: \'NoneType\' object has no attribute \'copy\'\n'}
{'2020-08-05 15:46:01.588245': 'Traceback (most recent call last):\n  File "C:\\Users\\Dominic\\training-diary\\training-diary-backend\\flask_apis\\User.py", line 104, in get_all_data\n    return make_response(self.__auth.get_db_access().get_all_data(), 200, response_header)\n  File "C:\\Users\\Dominic\\training-diary\\training-diary-backend\\database_access\\DbAccess.py", line 36, in get_all_data\n    data = self.__document.copy()\nAttributeError: \'NoneType\' object has no attribute \'copy\'\n'}
{'2020-08-05 15:54:15.733212': 'Traceback (most recent call last):\n  File "C:\\Users\\Dominic\\training-diary\\training-diary-backend\\flask_apis\\User.py", line 104, in get_all_data\n    return make_response(self.__auth.get_db_access().get_all_data(), 200, response_header)\n  File "C:\\Users\\Dominic\\training-diary\\training-diary-backend\\database_access\\DbAccess.py", line 36, in get_all_data\n    data = self.__document.copy()\nAttributeError: \'NoneType\' object has no attribute \'copy\'\n'}
{'2020-08-05 16:29:04.791339': 'Traceback (most recent call last):\n  File "C:\\Users\\Dominic\\training-diary\\training-diary-backend\\flask_apis\\User.py", line 107, in get_all_data\n    return make_response(self.__auth.get_db_access().get_all_data(), 200, response_header)\n  File "C:\\Users\\Dominic\\training-diary\\training-diary-backend\\database_access\\DbAccess.py", line 36, in get_all_data\n    data = self.__document.copy()\nAttributeError: \'NoneType\' object has no attribute \'copy\'\n'}
{'2020-08-05 22:52:36.892445': 'Traceback (most recent call last):\n  File "C:\\Users\\Dominic\\training-diary\\training-diary-backend\\flask_apis\\User.py", line 103, in get_all_data\n    return make_response(self.__auth.get_db_access().get_all_data(), 200, response_header)\n  File "C:\\Users\\Dominic\\training-diary\\training-diary-backend\\database_access\\DbAccess.py", line 36, in get_all_data\n    data = self.__document.copy()\nAttributeError: \'NoneType\' object has no attribute \'copy\'\n'}
{'2020-08-06 17:16:56.402044': 'Traceback (most recent call last):\n  File "C:\\Users\\Dominic\\training-diary\\training-diary-backend\\flask_apis\\User.py", line 107, in generate_temp_credentials\n    TdBot.send_recovery_account_message(self.__sender, recovery_email_msg)\n  File "C:\\Users\\Dominic\\training-diary\\training-diary-backend\\user_authentication\\TdBot.py", line 65, in send_recovery_account_message\n    service = get_service_obj()\n  File "C:\\Users\\Dominic\\training-diary\\training-diary-backend\\user_authentication\\TdBot.py", line 26, in get_service_obj\n    \'credentials.json\', SCOPES)\n  File "D:\\Program Files\\lib\\site-packages\\google_auth_oauthlib\\flow.py", line 196, in from_client_secrets_file\n    with open(client_secrets_file, \'r\') as json_file:\nFileNotFoundError: [Errno 2] No such file or directory: \'credentials.json\'\n'}
{'2020-08-06 17:19:33.713658': 'Traceback (most recent call last):\n  File "C:\\Users\\Dominic\\training-diary\\training-diary-backend\\flask_apis\\User.py", line 107, in generate_temp_credentials\n    TdBot.send_recovery_account_message(self.__sender, recovery_email_msg)\n  File "C:\\Users\\Dominic\\training-diary\\training-diary-backend\\user_authentication\\TdBot.py", line 65, in send_recovery_account_message\n    service = get_service_obj()\n  File "C:\\Users\\Dominic\\training-diary\\training-diary-backend\\user_authentication\\TdBot.py", line 26, in get_service_obj\n    \'credentials.json\', SCOPES)\n  File "D:\\Program Files\\lib\\site-packages\\google_auth_oauthlib\\flow.py", line 196, in from_client_secrets_file\n    with open(client_secrets_file, \'r\') as json_file:\nFileNotFoundError: [Errno 2] No such file or directory: \'credentials.json\'\n'}
{'2020-08-06 17:24:30.333677': 'Traceback (most recent call last):\n  File "C:\\Users\\Dominic\\training-diary\\training-diary-backend\\flask_apis\\User.py", line 107, in generate_temp_credentials\n    TdBot.send_recovery_account_message(self.__sender, recovery_email_msg)\nTypeError: send_recovery_account_message() missing 1 required positional argument: \'message\'\n'}
{'2020-08-06 17:25:32.555784': 'Traceback (most recent call last):\n  File "C:\\Users\\Dominic\\training-diary\\training-diary-backend\\flask_apis\\User.py", line 107, in generate_temp_credentials\n    TdBot.send_recovery_account_message(self.__sender, recovery_email_msg)\n  File "C:\\Users\\Dominic\\training-diary\\training-diary-backend\\user_authentication\\TdBot.py", line 70, in send_recovery_account_message\n    service = get_service_obj()\n  File "C:\\Users\\Dominic\\training-diary\\training-diary-backend\\user_authentication\\TdBot.py", line 30, in get_service_obj\n    \'credentials.json\', SCOPES)\n  File "D:\\Program Files\\lib\\site-packages\\google_auth_oauthlib\\flow.py", line 196, in from_client_secrets_file\n    with open(client_secrets_file, \'r\') as json_file:\nFileNotFoundError: [Errno 2] No such file or directory: \'credentials.json\'\n'}
{'2020-08-06 17:26:56.339561': 'Traceback (most recent call last):\n  File "C:\\Users\\Dominic\\training-diary\\training-diary-backend\\flask_apis\\User.py", line 107, in generate_temp_credentials\n    gmail_service_obj = TdBot.get_service_obj()\n  File "C:\\Users\\Dominic\\training-diary\\training-diary-backend\\user_authentication\\TdBot.py", line 30, in get_service_obj\n    \'credentials.json\', SCOPES)\n  File "D:\\Program Files\\lib\\site-packages\\google_auth_oauthlib\\flow.py", line 196, in from_client_secrets_file\n    with open(client_secrets_file, \'r\') as json_file:\nFileNotFoundError: [Errno 2] No such file or directory: \'credentials.json\'\n'}
{'2020-08-06 17:34:19.803462': 'Traceback (most recent call last):\n  File "C:\\Users\\Dominic\\training-diary\\training-diary-backend\\flask_apis\\User.py", line 175, in generate_temp_credentials\n    gmail_service_obj = self.get_service_obj()\n  File "C:\\Users\\Dominic\\training-diary\\training-diary-backend\\flask_apis\\User.py", line 38, in get_service_obj\n    \'credentials.json\', SCOPES)\n  File "D:\\Program Files\\lib\\site-packages\\google_auth_oauthlib\\flow.py", line 196, in from_client_secrets_file\n    with open(client_secrets_file, \'r\') as json_file:\nFileNotFoundError: [Errno 2] No such file or directory: \'credentials.json\'\n'}
{'2020-08-10 23:44:03.018380': 'Traceback (most recent call last):\n  File "C:\\Users\\Dominic\\training-diary\\training-diary-backend\\flask_apis\\User.py", line 213, in get_all_data\n    return make_response(self.__auth.get_db_access().get_all_data(), 200, response_header)\n  File "C:\\Users\\Dominic\\training-diary\\training-diary-backend\\database_access\\DbAccess.py", line 36, in get_all_data\n    data = self.__document.copy()\nAttributeError: \'NoneType\' object has no attribute \'copy\'\n'}
{'2020-08-10 23:45:14.362621': 'Traceback (most recent call last):\n  File "C:\\Users\\Dominic\\training-diary\\training-diary-backend\\flask_apis\\User.py", line 213, in get_all_data\n    return make_response(self.__auth.get_db_access().get_all_data(), 200, response_header)\n  File "C:\\Users\\Dominic\\training-diary\\training-diary-backend\\database_access\\DbAccess.py", line 36, in get_all_data\n    data = self.__document.copy()\nAttributeError: \'NoneType\' object has no attribute \'copy\'\n'}
{'2020-08-10 23:45:49.673527': 'Traceback (most recent call last):\n  File "C:\\Users\\Dominic\\training-diary\\training-diary-backend\\flask_apis\\User.py", line 213, in get_all_data\n    return make_response(self.__auth.get_db_access().get_all_data(), 200, response_header)\n  File "C:\\Users\\Dominic\\training-diary\\training-diary-backend\\database_access\\DbAccess.py", line 36, in get_all_data\n    data = self.__document.copy()\nAttributeError: \'NoneType\' object has no attribute \'copy\'\n'}
{'2020-08-11 12:52:49.556122': 'Traceback (most recent call last):\n  File "C:\\Users\\Dominic\\training-diary\\training-diary-backend\\flask_apis\\User.py", line 213, in get_all_data\n    return make_response(self.__auth.get_db_access().get_all_data(), 200, response_header)\n  File "C:\\Users\\Dominic\\training-diary\\training-diary-backend\\database_access\\DbAccess.py", line 36, in get_all_data\n    data = self.__document.copy()\nAttributeError: \'NoneType\' object has no attribute \'copy\'\n'}
{'2020-08-11 12:54:31.705830': 'Traceback (most recent call last):\n  File "C:\\Users\\Dominic\\training-diary\\training-diary-backend\\flask_apis\\User.py", line 213, in get_all_data\n    return make_response(self.__auth.get_db_access().get_all_data(), 200, response_header)\n  File "C:\\Users\\Dominic\\training-diary\\training-diary-backend\\database_access\\DbAccess.py", line 36, in get_all_data\n    data = self.__document.copy()\nAttributeError: \'NoneType\' object has no attribute \'copy\'\n'}
{'2020-08-11 12:54:43.595662': 'Traceback (most recent call last):\n  File "C:\\Users\\Dominic\\training-diary\\training-diary-backend\\flask_apis\\User.py", line 213, in get_all_data\n    return make_response(self.__auth.get_db_access().get_all_data(), 200, response_header)\n  File "C:\\Users\\Dominic\\training-diary\\training-diary-backend\\database_access\\DbAccess.py", line 36, in get_all_data\n    data = self.__document.copy()\nAttributeError: \'NoneType\' object has no attribute \'copy\'\n'}
{'2020-08-11 12:55:15.187977': 'Traceback (most recent call last):\n  File "C:\\Users\\Dominic\\training-diary\\training-diary-backend\\flask_apis\\User.py", line 213, in get_all_data\n    return make_response(self.__auth.get_db_access().get_all_data(), 200, response_header)\n  File "C:\\Users\\Dominic\\training-diary\\training-diary-backend\\database_access\\DbAccess.py", line 36, in get_all_data\n    data = self.__document.copy()\nAttributeError: \'NoneType\' object has no attribute \'copy\'\n'}
{'2020-08-11 12:55:43.325716': 'Traceback (most recent call last):\n  File "C:\\Users\\Dominic\\training-diary\\training-diary-backend\\flask_apis\\User.py", line 213, in get_all_data\n    return make_response(self.__auth.get_db_access().get_all_data(), 200, response_header)\n  File "C:\\Users\\Dominic\\training-diary\\training-diary-backend\\database_access\\DbAccess.py", line 36, in get_all_data\n    data = self.__document.copy()\nAttributeError: \'NoneType\' object has no attribute \'copy\'\n'}
{'2020-08-11 12:55:58.934578': 'Traceback (most recent call last):\n  File "C:\\Users\\Dominic\\training-diary\\training-diary-backend\\flask_apis\\User.py", line 213, in get_all_data\n    return make_response(self.__auth.get_db_access().get_all_data(), 200, response_header)\n  File "C:\\Users\\Dominic\\training-diary\\training-diary-backend\\database_access\\DbAccess.py", line 36, in get_all_data\n    data = self.__document.copy()\nAttributeError: \'NoneType\' object has no attribute \'copy\'\n'}
{'2020-08-11 12:57:36.581495': 'Traceback (most recent call last):\n  File "C:\\Users\\Dominic\\training-diary\\training-diary-backend\\flask_apis\\User.py", line 213, in get_all_data\n    return make_response(self.__auth.get_db_access().get_all_data(), 200, response_header)\n  File "C:\\Users\\Dominic\\training-diary\\training-diary-backend\\database_access\\DbAccess.py", line 36, in get_all_data\n    data = self.__document.copy()\nAttributeError: \'NoneType\' object has no attribute \'copy\'\n'}
{'2020-08-11 12:59:04.666778': 'Traceback (most recent call last):\n  File "C:\\Users\\Dominic\\training-diary\\training-diary-backend\\flask_apis\\User.py", line 213, in get_all_data\n    return make_response(self.__auth.get_db_access().get_all_data(), 200, response_header)\n  File "C:\\Users\\Dominic\\training-diary\\training-diary-backend\\database_access\\DbAccess.py", line 36, in get_all_data\n    data = self.__document.copy()\nAttributeError: \'NoneType\' object has no attribute \'copy\'\n'}
{'2020-08-13 22:47:59.398876': 'Traceback (most recent call last):\n  File "C:\\Users\\Dominic\\training-diary\\training-diary\\flask_apis\\User.py", line 191, in generate_temp_credentials\n    recovery_email_msg = self.create_recovery_account_message(self.__sender, email, self.__recovery_subject, msg)\nUnboundLocalError: local variable \'msg\' referenced before assignment\n'}
{'2020-08-13 22:49:37.015411': 'Traceback (most recent call last):\n  File "C:\\Users\\Dominic\\training-diary\\training-diary\\flask_apis\\User.py", line 195, in generate_temp_credentials\n    mail_obj.send(msg)\n  File "D:\\Program Files\\lib\\site-packages\\flask_mail.py", line 491, in send\n    with self.connect() as connection:\n  File "D:\\Program Files\\lib\\site-packages\\flask_mail.py", line 144, in __enter__\n    self.host = self.configure_host()\n  File "D:\\Program Files\\lib\\site-packages\\flask_mail.py", line 158, in configure_host\n    host = smtplib.SMTP(self.mail.server, self.mail.port)\n  File "D:\\Program Files\\lib\\smtplib.py", line 251, in __init__\n    (code, msg) = self.connect(host, port)\n  File "D:\\Program Files\\lib\\smtplib.py", line 336, in connect\n    self.sock = self._get_socket(host, port, self.timeout)\n  File "D:\\Program Files\\lib\\smtplib.py", line 307, in _get_socket\n    self.source_address)\n  File "D:\\Program Files\\lib\\socket.py", line 727, in create_connection\n    raise err\n  File "D:\\Program Files\\lib\\socket.py", line 716, in create_connection\n    sock.connect(sa)\nConnectionRefusedError: [WinError 10061] No connection could be made because the target machine actively refused it\n'}
{'2020-08-13 22:53:52.015522': 'Traceback (most recent call last):\n  File "C:\\Users\\Dominic\\training-diary\\training-diary\\flask_apis\\User.py", line 195, in generate_temp_credentials\n    mail_obj.send(msg)\n  File "D:\\Program Files\\lib\\site-packages\\flask_mail.py", line 491, in send\n    with self.connect() as connection:\n  File "D:\\Program Files\\lib\\site-packages\\flask_mail.py", line 144, in __enter__\n    self.host = self.configure_host()\n  File "D:\\Program Files\\lib\\site-packages\\flask_mail.py", line 165, in configure_host\n    host.login(self.mail.username, self.mail.password)\n  File "D:\\Program Files\\lib\\smtplib.py", line 730, in login\n    raise last_exception\n  File "D:\\Program Files\\lib\\smtplib.py", line 721, in login\n    initial_response_ok=initial_response_ok)\n  File "D:\\Program Files\\lib\\smtplib.py", line 642, in auth\n    raise SMTPAuthenticationError(code, resp)\nsmtplib.SMTPAuthenticationError: (535, b\'5.7.8 Username and Password not accepted. Learn more at\\n5.7.8  https://support.google.com/mail/?p=BadCredentials n2sm6777779pgv.37 - gsmtp\')\n'}
